# 谜题 41：域和流  

## 背景

 finally 语句块异常处理。

## 代码 

下面的方法将一个文件拷贝到另一个文件，并且被设计为要关闭它所创建的每一个流，即使它碰到 I/O 错误也要如此。

遗憾的是，它并非总是能够做到这一点。  

```java
static void copy(String src, String dest) throws IOException {
    InputStream in = null;
    OutputStream out = null;

    try {
        in = new FileInputStream(src);
        out = new FileOutputStream(dest);
        byte[] buf = new byte[1024];
        int n;

        while ((n = in.read(buf)) > 0)
            out.write(buf, 0, n);
    } finally {
        if (in != null) 
            in.close();
        if (out != null) 
            out.close();
    }
}
```

## 陷阱

在拷贝操作引发了一个IOException 的情况下，finally 语句块也会在方法返回之前执行。出什么错了呢？

## 解惑

问题在 finally 语句块自身中。

close 方法也可能会抛出 IOException 异常。如果这正好发生在 in.close 被调用之时，那么这个异常就会阻止 out.close 被调用，从而使输出流仍保持在开放状态。  

## 解决办法或规则

**修正**：解决方式是将每一个 close 都包装在一个嵌套的 try 语句块中。下面的 finally语句块的版本可以保证在两个流上都会调用 close：  

```java
} finally {
    if (in != null) {
        try {
            in.close();
        } catch (IOException ex) {
            // There is nothing we can do if close fails
        }

        if (out != null)
            try {
                out.close();
            } catch (IOException ex) {
                // There is nothing we can do if close fails
            }
    }
}
```

从 5.0 版本开始，你可以对代码进行重构，以利用 Closeable 接口：  

```java
} finally {
    closeIgnoringException(in);
    closeIgnoringEcception(out);
}

private static void closeIgnoringException(Closeable c) {
    if (c != null) {
        try {
            c.close();
        } catch (IOException ex) {
            // There is nothing we can do if close fails
        }
    }
}
```

总之，当你在 finally 语句块中调用 close 方法时，要用一个嵌套的 try-catch语句来保护它，以防止 IOException 的传播。

更一般地讲，**对于任何在 finally语句块中可能会抛出的被检查异常都要进行处理，而不是任其传播**。