# 谜题 40：不情愿的构造器  

## 背景

实例初始化异常。

## 代码

下面的程序就有这样的一个声明。那么，它将打印出什么呢？  

```java
public class Reluctant {
    private Reluctant internalInstance = new Reluctant();

    public Reluctant() throws Exception {
        throw new Exception("I'm not coming out");
    }

    public static void main(String[] args) {
        try {
            Reluctant b = new Reluctant();
            System.out.println("Surprise!");
        } catch (Exception ex) {
            System.out.println("I told you so");
        }
    }
}
```

## 陷阱

main 方法调用了 Reluctant 构造器，它将抛出一个异常。你可能期望 catch 子句能够捕获这个异常，并且打印 I told you so。  

但是当你尝试着去运行它时，就会发现它压根没有去做这类的事情：它抛出了 StackOverflowError 异常，为什么呢？  

与大多数抛出 StackOverflowError 异常的程序一样，本程序也包含了一个无限递归。  

## 解惑

与大多数抛出 StackOverflowError 异常的程序一样，本程序也包含了一个无限递归。

**当你调用一个构造器时，实例变量的初始化操作，将先于构造器的程序体而运行**。在本谜题中， internalInstance 变量的初始化操作递归调用了构造器，而该构造器通过再次调用 Reluctant 构造器而初始化该变量自己的internalInstance 域，如此无限递归下去。这些递归调用在构造器程序体获得执行机会之前就会抛出 StackOverflowError 异常，因为 StackOverflowError是 Error 的子类型而不是 Exception 的子类型，所以 catch 子句无法捕获它。  

## 解决办法或规则

**教训**：对于**一个对象包含与它自己类型相同的实例的情况，必须非常小心地初始化这样的包含实例，以避免 StackOverflowError 异常**。例如，链接列表节点、树节点和图节点都属于这种情况。  

总之，**实例初始化操作是先于构造器的程序体而运行的，实例初始化操作抛出的任何异常都会传播给构造器**。**如果初始化操作抛出的是被检查异常，那么构造器必须声明也会抛出这些异常，但是应该避免这样做，因为它会造成混乱**。

最后，对于我们所设计的类，如果其实例包含同样属于这个类的其他实例，那么对这种无限递归要格外当心。  